2018-10-02 11:16:55,282 (47329/MainThread) pgcli.main INFO - No default pager found in environment. Using os default pager
2018-10-02 11:33:43,191 (48063/MainThread) pgcli.main INFO - No default pager found in environment. Using os default pager
2018-10-02 11:33:46,931 (48068/MainThread) pgcli.main INFO - No default pager found in environment. Using os default pager
2018-10-02 11:33:46,939 (48068/MainThread) pgcli.main ERROR - traceback: 'Traceback (most recent call last):\n  File "/usr/local/Cellar/pgcli/1.10.3/libexec/lib/python2.7/site-packages/pgcli/main.py", line 474, in connect\n    raise e\nOperationalError: FATAL:  database "danny" does not exist\n\n'
2018-10-02 11:33:55,121 (48073/MainThread) pgcli.main INFO - No default pager found in environment. Using os default pager
2018-10-02 11:43:12,138 (49476/MainThread) pgcli.main INFO - No default pager found in environment. Using os default pager
2018-10-02 11:44:03,351 (49510/MainThread) pgcli.main INFO - No default pager found in environment. Using os default pager
2018-10-02 11:45:08,214 (49529/MainThread) pgcli.main INFO - No default pager found in environment. Using os default pager
2018-10-02 11:45:08,221 (49529/MainThread) pgcli.main ERROR - traceback: 'Traceback (most recent call last):\n  File "/usr/local/Cellar/pgcli/1.10.3/libexec/lib/python2.7/site-packages/pgcli/main.py", line 474, in connect\n    raise e\nOperationalError: could not connect to server: No such file or directory\n\tIs the server running locally and accepting\n\tconnections on Unix domain socket "/tmp/.s.PGSQL.5432"?\n\n'
2018-10-02 11:45:23,705 (49689/MainThread) pgcli.main INFO - No default pager found in environment. Using os default pager
2018-10-02 11:45:23,713 (49689/MainThread) pgcli.main ERROR - traceback: 'Traceback (most recent call last):\n  File "/usr/local/Cellar/pgcli/1.10.3/libexec/lib/python2.7/site-packages/pgcli/main.py", line 474, in connect\n    raise e\nOperationalError: FATAL:  database "danny" does not exist\n\n'
2018-10-02 11:45:28,556 (49693/MainThread) pgcli.main INFO - No default pager found in environment. Using os default pager
2018-10-02 11:47:20,563 (49714/MainThread) pgcli.main INFO - No default pager found in environment. Using os default pager
2018-10-02 11:47:20,572 (49714/MainThread) pgcli.main ERROR - traceback: 'Traceback (most recent call last):\n  File "/usr/local/Cellar/pgcli/1.10.3/libexec/lib/python2.7/site-packages/pgcli/main.py", line 474, in connect\n    raise e\nOperationalError: FATAL:  role "postgres" does not exist\n\n'
2018-10-02 11:47:28,628 (49718/MainThread) pgcli.main INFO - No default pager found in environment. Using os default pager
2018-10-02 11:47:28,636 (49718/MainThread) pgcli.main ERROR - traceback: 'Traceback (most recent call last):\n  File "/usr/local/Cellar/pgcli/1.10.3/libexec/lib/python2.7/site-packages/pgcli/main.py", line 474, in connect\n    raise e\nOperationalError: FATAL:  database "danny" does not exist\n\n'
2018-10-02 11:47:34,238 (49722/MainThread) pgcli.main INFO - No default pager found in environment. Using os default pager
2018-10-02 11:49:29,808 (49912/MainThread) pgcli.main INFO - No default pager found in environment. Using os default pager
2018-10-02 11:51:44,986 (50092/MainThread) pgcli.main INFO - No default pager found in environment. Using os default pager
2018-10-02 11:53:53,161 (50129/MainThread) pgcli.main INFO - No default pager found in environment. Using os default pager
2018-10-02 11:54:09,502 (50137/MainThread) pgcli.main INFO - No default pager found in environment. Using os default pager
2018-10-03 10:44:04,444 (6462/MainThread) pgcli.main INFO - No default pager found in environment. Using os default pager
2018-10-04 10:18:45,478 (28243/MainThread) pgcli.main INFO - No default pager found in environment. Using os default pager
2018-10-04 10:28:36,174 (28243/MainThread) pgcli.pgexecute ERROR - sql: u'\\t users_profile', error: ProgrammingError('syntax error at or near "\\"\nLINE 1: \\t users_profile\n        ^\n',)
2018-10-04 10:28:36,174 (28243/MainThread) pgcli.pgexecute ERROR - traceback: 'Traceback (most recent call last):\n  File "/usr/local/Cellar/pgcli/1.10.3/libexec/lib/python2.7/site-packages/pgcli/pgexecute.py", line 357, in run\n    yield self.execute_normal_sql(sql) + (sql, True, False)\n  File "/usr/local/Cellar/pgcli/1.10.3/libexec/lib/python2.7/site-packages/pgcli/pgexecute.py", line 389, in execute_normal_sql\n    cur.execute(split_sql)\nProgrammingError: syntax error at or near "\\"\nLINE 1: \\t users_profile\n        ^\n\n'
2018-10-05 12:49:22,971 (43045/MainThread) pgcli.main INFO - No default pager found in environment. Using os default pager
2018-10-08 14:32:07,846 (55222/MainThread) pgcli.main INFO - No default pager found in environment. Using os default pager
2018-10-09 11:14:06,721 (81091/MainThread) pgcli.main INFO - No default pager found in environment. Using os default pager
2018-10-09 17:22:57,731 (96264/MainThread) pgcli.main INFO - No default pager found in environment. Using os default pager
2018-10-10 16:34:01,904 (23604/MainThread) pgcli.main INFO - No default pager found in environment. Using os default pager
2018-10-10 17:15:26,656 (24947/MainThread) pgcli.main INFO - No default pager found in environment. Using os default pager
2018-10-10 21:00:54,465 (26864/MainThread) pgcli.main INFO - No default pager found in environment. Using os default pager
2018-10-10 21:03:40,880 (26864/MainThread) pgcli.pgexecute ERROR - sql: u"insert into stores_clientterritory (name, description, created_at, updated_at, client_id, parent_id) values ('foo', 'bar', now(), now(), 1, 36)", error: IntegrityError('insert or update on table "stores_clientterritory" violates foreign key constraint "stores_clientterrito_parent_id_03bb194e_fk_stores_cl"\nDETAIL:  Key (parent_id)=(36) is not present in table "stores_clientterritory".\n',)
2018-10-10 21:03:40,881 (26864/MainThread) pgcli.pgexecute ERROR - traceback: 'Traceback (most recent call last):\n  File "/usr/local/Cellar/pgcli/1.10.3/libexec/lib/python2.7/site-packages/pgcli/pgexecute.py", line 357, in run\n    yield self.execute_normal_sql(sql) + (sql, True, False)\n  File "/usr/local/Cellar/pgcli/1.10.3/libexec/lib/python2.7/site-packages/pgcli/pgexecute.py", line 389, in execute_normal_sql\n    cur.execute(split_sql)\nIntegrityError: insert or update on table "stores_clientterritory" violates foreign key constraint "stores_clientterrito_parent_id_03bb194e_fk_stores_cl"\nDETAIL:  Key (parent_id)=(36) is not present in table "stores_clientterritory".\n\n'
2018-10-10 21:03:55,015 (26864/MainThread) pgcli.pgexecute ERROR - sql: u"insert into stores_clientterritory (name, description, created_at, updated_at, client_id, parent_id) values ('foo', 'bar', now(), now(), 1, 35)", error: IntegrityError('insert or update on table "stores_clientterritory" violates foreign key constraint "stores_clientterrito_parent_id_03bb194e_fk_stores_cl"\nDETAIL:  Key (parent_id)=(35) is not present in table "stores_clientterritory".\n',)
2018-10-10 21:03:55,015 (26864/MainThread) pgcli.pgexecute ERROR - traceback: 'Traceback (most recent call last):\n  File "/usr/local/Cellar/pgcli/1.10.3/libexec/lib/python2.7/site-packages/pgcli/pgexecute.py", line 357, in run\n    yield self.execute_normal_sql(sql) + (sql, True, False)\n  File "/usr/local/Cellar/pgcli/1.10.3/libexec/lib/python2.7/site-packages/pgcli/pgexecute.py", line 389, in execute_normal_sql\n    cur.execute(split_sql)\nIntegrityError: insert or update on table "stores_clientterritory" violates foreign key constraint "stores_clientterrito_parent_id_03bb194e_fk_stores_cl"\nDETAIL:  Key (parent_id)=(35) is not present in table "stores_clientterritory".\n\n'
2018-10-10 21:11:13,275 (26864/MainThread) pgcli.pgexecute ERROR - sql: u"insert into stores_clientterritory (name, description, created_at, updated_at, client_id\\ values ('foo', 'bar', now(), now(), 1)", error: ProgrammingError('syntax error at or near "\\"\nLINE 1: ...me, description, created_at, updated_at, client_id\\ values (...\n                                                             ^\n',)
2018-10-10 21:11:13,275 (26864/MainThread) pgcli.pgexecute ERROR - traceback: 'Traceback (most recent call last):\n  File "/usr/local/Cellar/pgcli/1.10.3/libexec/lib/python2.7/site-packages/pgcli/pgexecute.py", line 357, in run\n    yield self.execute_normal_sql(sql) + (sql, True, False)\n  File "/usr/local/Cellar/pgcli/1.10.3/libexec/lib/python2.7/site-packages/pgcli/pgexecute.py", line 389, in execute_normal_sql\n    cur.execute(split_sql)\nProgrammingError: syntax error at or near "\\"\nLINE 1: ...me, description, created_at, updated_at, client_id\\ values (...\n                                                             ^\n\n'
2018-10-10 21:11:51,147 (26864/MainThread) pgcli.pgexecute ERROR - sql: u'insert into stores_clientterritory_stores (clientterritory_id, storelocation_id) values (1, 35)', error: IntegrityError('insert or update on table "stores_clientterritory_stores" violates foreign key constraint "stores_clientterrito_clientterritory_id_22c1c081_fk_stores_cl"\nDETAIL:  Key (clientterritory_id)=(1) is not present in table "stores_clientterritory".\n',)
2018-10-10 21:11:51,147 (26864/MainThread) pgcli.pgexecute ERROR - traceback: 'Traceback (most recent call last):\n  File "/usr/local/Cellar/pgcli/1.10.3/libexec/lib/python2.7/site-packages/pgcli/pgexecute.py", line 357, in run\n    yield self.execute_normal_sql(sql) + (sql, True, False)\n  File "/usr/local/Cellar/pgcli/1.10.3/libexec/lib/python2.7/site-packages/pgcli/pgexecute.py", line 389, in execute_normal_sql\n    cur.execute(split_sql)\nIntegrityError: insert or update on table "stores_clientterritory_stores" violates foreign key constraint "stores_clientterrito_clientterritory_id_22c1c081_fk_stores_cl"\nDETAIL:  Key (clientterritory_id)=(1) is not present in table "stores_clientterritory".\n\n'
2018-10-12 15:17:31,119 (49682/MainThread) pgcli.main INFO - No default pager found in environment. Using os default pager
2018-10-12 15:17:57,144 (49682/MainThread) pgcli.pgexecute ERROR - sql: u'table client', error: ProgrammingError('relation "client" does not exist\nLINE 1: table client\n              ^\n',)
2018-10-12 15:17:57,145 (49682/MainThread) pgcli.pgexecute ERROR - traceback: 'Traceback (most recent call last):\n  File "/usr/local/Cellar/pgcli/1.10.3/libexec/lib/python2.7/site-packages/pgcli/pgexecute.py", line 357, in run\n    yield self.execute_normal_sql(sql) + (sql, True, False)\n  File "/usr/local/Cellar/pgcli/1.10.3/libexec/lib/python2.7/site-packages/pgcli/pgexecute.py", line 389, in execute_normal_sql\n    cur.execute(split_sql)\nProgrammingError: relation "client" does not exist\nLINE 1: table client\n              ^\n\n'
2018-10-12 19:53:34,717 (56821/MainThread) pgcli.main INFO - No default pager found in environment. Using os default pager
2018-10-12 19:53:34,724 (56821/MainThread) pgcli.main ERROR - traceback: 'Traceback (most recent call last):\n  File "/usr/local/Cellar/pgcli/1.10.3/libexec/lib/python2.7/site-packages/pgcli/main.py", line 474, in connect\n    raise e\nOperationalError: FATAL:  database "jyve_test" does not exist\n\n'
2018-10-12 19:53:56,187 (56959/MainThread) pgcli.main INFO - No default pager found in environment. Using os default pager
2018-10-12 19:54:06,912 (56959/MainThread) pgcli.pgexecute ERROR - sql: u'd_', error: ProgrammingError('syntax error at or near "d_"\nLINE 1: d_\n        ^\n',)
2018-10-12 19:54:06,913 (56959/MainThread) pgcli.pgexecute ERROR - traceback: 'Traceback (most recent call last):\n  File "/usr/local/Cellar/pgcli/1.10.3/libexec/lib/python2.7/site-packages/pgcli/pgexecute.py", line 357, in run\n    yield self.execute_normal_sql(sql) + (sql, True, False)\n  File "/usr/local/Cellar/pgcli/1.10.3/libexec/lib/python2.7/site-packages/pgcli/pgexecute.py", line 389, in execute_normal_sql\n    cur.execute(split_sql)\nProgrammingError: syntax error at or near "d_"\nLINE 1: d_\n        ^\n\n'
2018-10-12 19:54:08,735 (56959/MainThread) pgcli.pgexecute ERROR - sql: u'\\d_', error: ProgrammingError('syntax error at or near "\\"\nLINE 1: \\d_\n        ^\n',)
2018-10-12 19:54:08,736 (56959/MainThread) pgcli.pgexecute ERROR - traceback: 'Traceback (most recent call last):\n  File "/usr/local/Cellar/pgcli/1.10.3/libexec/lib/python2.7/site-packages/pgcli/pgexecute.py", line 357, in run\n    yield self.execute_normal_sql(sql) + (sql, True, False)\n  File "/usr/local/Cellar/pgcli/1.10.3/libexec/lib/python2.7/site-packages/pgcli/pgexecute.py", line 389, in execute_normal_sql\n    cur.execute(split_sql)\nProgrammingError: syntax error at or near "\\"\nLINE 1: \\d_\n        ^\n\n'
2018-10-12 19:54:11,834 (56959/MainThread) pgcli.pgexecute ERROR - sql: u'\\dd', error: ProgrammingError('syntax error at or near "\\"\nLINE 1: \\dd\n        ^\n',)
2018-10-12 19:54:11,834 (56959/MainThread) pgcli.pgexecute ERROR - traceback: 'Traceback (most recent call last):\n  File "/usr/local/Cellar/pgcli/1.10.3/libexec/lib/python2.7/site-packages/pgcli/pgexecute.py", line 357, in run\n    yield self.execute_normal_sql(sql) + (sql, True, False)\n  File "/usr/local/Cellar/pgcli/1.10.3/libexec/lib/python2.7/site-packages/pgcli/pgexecute.py", line 389, in execute_normal_sql\n    cur.execute(split_sql)\nProgrammingError: syntax error at or near "\\"\nLINE 1: \\dd\n        ^\n\n'
2018-10-12 19:54:33,559 (57059/MainThread) pgcli.main INFO - No default pager found in environment. Using os default pager
